Workbook

Sheet Overview
B1: Real Projects DIGITALIZATION
A5: Name: | B5: Tim Weidenberg
A6: Faculty: | B6: 10
A7: Team: | B7: OGAP

Sheet Persona
B27: Anna Weber is a hypothesis-driven proto-persona created to represent a broad target group for our parking app rather than a specific individual or narrowly defined demographic segment. The persona was developed during the early product discovery phase to structure assumptions, support ideation, and align the team. The persona is informed by a combination of desk research, secondary sources, and observed urban parking behavior, particularly in dense residential areas such as Munich. In addition, it draws from informal conversations with people about the app and their parking experiences. These discussions were exploratory and conversational in nature and not systematically documented or analyzed, and therefore should be understood as directional input rather than formal user research. Our survey and quantitative research did not collect demographic data such as age, gender, or occupation. As a result, all demographic attributes in this persona—name, age, gender, profession, and location—are fictional and illustrative. They are included solely to humanize the target group and make shared problem spaces easier to communicate within the team. Rather than representing a single user type, Anna stands for a wide range of urban drivers who rely on their car for daily mobility, park primarily on-street, and regularly experience uncertainty, stress, and time loss when searching for parking. The outlined pain points and needs reflect common behavioral patterns and recurring themes identified across secondary research and informal discussions, not validated personal characteristics. This persona serves as a working model and communication tool that makes assumptions explicit and intentionally avoids over-segmentation. It provides a foundation for early product decisions while remaining open to refinement. As more structured qualitative and quantitative research is conducted, the persona and underlying assumptions will be validated, adjusted, or expanded to better reflect the diversity of the app’s target group.

Sheet Question Survey
B2: Overview Questions
B4: Fragebogen: Autofahren und Parken in München Besitzen Sie ein Auto bzw. haben Sie regelmäßig Zugang zu einem Auto? ☐ Ja ☐ Nein Wie häufig sind Sie mit dem Auto innerhalb München unterwegs? ☐ Täglich ☐ Mehrmals pro Woche ☐ Selten ☐ Nie Wie zufrieden sind Sie insgesamt mit der Verkehrssituation in München? ☐ Sehr zufrieden ☐ Eher zufrieden ☐ Eher unzufrieden ☐ Sehr unzufrieden Wie oft haben Sie Schwierigkeiten, einen Parkplatz zu finden? ☐ Sehr häufig ☐ Häufig ☐ Selten ☐ Nie Wie lange dauert Ihre durchschnittliche Parkplatzsuche? ☐ Unter 5 Minuten ☐ 5–10 Minuten ☐ 10–20 Minuten ☐ Über 20 Minuten Wo parken Sie meist? ☐ Anwohnerparkzone ☐ Öffentlicher Straßenraum ☐ Parkhaus / Tiefgarage ☐ Eigener Stellplatz ☐ Sonstiges: ___________ Wie empfinden Sie die Parkgebühren in München? ☐ Angemessen ☐ Zu hoch ☐ Zu niedrig ☐ Keine Meinung Welche Maßnahmen würden Sie persönlich am meisten unterstützen? (Max. 2 auswählen) ☐ Ausbau digitaler Parkleitsysteme ☐ Mehr Stellplätze / Parkhäuser ☐ Bessere Verkehslenkung / weniger Suchverkehr ☐ Förderung von Alternativen (ÖPNV, P+R, Carsharing) ☐ Sonstiges: ___________ Wie wahrscheinlich ist es, dass Sie in Zukunft häufiger auf andere Verkehrsmittel (ÖPNV, Fahrrad etc.) umsteigen? ☐ Sehr wahrscheinlich ☐ Eher wahrscheinlich ☐ Eher unwahrscheinlich ☐ Sehr unwahrscheinlich Wären Sie bereit, für reservierte Stellülätze oder App-basierte Systeme zu bezahlen? ☐ Ja ☐ Nein Gibt es etwas, das Sie der Stadt München in Bezug auf Autofahren und Parken mitteilen möchten? (Offene Antwort)

Sheet Results Survey
B2: Overview Survey
B4: As part of our project, we conducted a user survey to better understand the current parking situation in Munich from the perspective of everyday drivers. The objective was to identify recurring challenges, quantify the severity of the problem, and establish a data-driven basis for further concept and solution development. Methodology and Data Collection The survey was designed as an online questionnaire and focused on five core aspects of urban parking behavior: 1. Car ownership and regular usage 2. Frequency of driving within Munich 3. Average duration of parking spot searches 4. Frequency of difficulties when finding a parking space 5. Overall satisfaction with the current parking situation At the time of analysis and documentation, 21 participants had completed the survey. The results were captured in the form of screenshots and visualized using bar charts. By the time the survey was officially closed, the total number of participants had increased to approximately 30. Unfortunately, the survey platform no longer provides access to the final aggregated results. As a result, the visual data presented in this project is based on the documented responses available before the survey ended. While the final number of responses is higher, the additional participants did not contradict the observed trends. The captured data therefore remains representative of the overall direction and key insights derived from the survey. Key Findings 1. High Car Usage Despite Strong Public Transport More than 80% of respondents stated that they either own or regularly use a car in Munich. This is noteworthy given the city’s extensive public transportation network and indicates that flexibility and convenience still play a crucial role in everyday mobility decisions. Additionally, over 60% of participants reported driving daily or several times per week within the city, reinforcing the relevance of parking availability as a frequent and recurring concern. 2. Time Lost Searching for Parking The survey shows that over 60% of respondents spend an average of 5–10 minutes searching for a parking space per trip. While this duration may appear moderate in isolation, it accumulates significantly over time—often resulting in hours lost each week. A smaller portion of respondents reported even longer search times, particularly during peak hours or in densely populated areas. 3. Frequent Difficulties Finding Parking Spaces More than 70% of participants indicated that they frequently or very frequently struggle to find an available parking spot. Only a minority reported rare difficulties, and none stated that they never experience parking-related issues. This highlights that parking scarcity in Munich is a persistent and widespread problem rather than an occasional inconvenience. 4. Overall Dissatisfaction with the Current Parking Situation When asked to evaluate their overall satisfaction, over half of respondents expressed dissatisfaction or strong dissatisfaction with the current parking situation in Munich. Notably, no participant selected the option “very satisfied.” This dissatisfaction directly correlates with the previously identified issues: time loss, stress, uncertainty, and increased traffic caused by circulating vehicles. Interpretation and Implications Taken together, the findings illustrate a clear pattern: • Cars remain a central mode of transport in Munich • Parking availability is limited and unpredictable • Drivers frequently spend time circling neighborhoods • This results in increased stress, traffic congestion, and unnecessary CO₂ emissions Even marginal improvements in parking efficiency could therefore have a substantial impact on urban mobility, environmental sustainability, and overall quality of life. Conclusion Through this survey, we were able to validate a real and pressing urban mobility problem using direct user feedback. Although the final survey count reached approximately 30 participants, the presented results are based on the documented data captured before the survey ended. These results remain valuable, as they clearly reveal consistent trends and recurring pain points. The survey findings provide a strong foundation for developing smarter, more efficient parking solutions and demonstrate that finding a parking space in Munich has evolved into a daily frustration rather than a simple task—with meaningful potential for improvement through data-driven and user-centered approaches.
P30: Preliminary results survey:

Sheet P&L --->

Sheet Explanation P&L
B2: Explanation Approach, Numbers, Sources
B4: The Excel file represents an integrated financial planning and forecasting model for a digital platform. The objective of the model is to transparently illustrate the economic development of the business over multiple periods. The model follows a clear bottom-up approach: starting from user growth, revenues are derived, combined with defined cost assumptions, and consolidated into a detailed operational profit and loss forecast. The model is structured into the tabs “Number of User,” “Information,” and, most importantly, “Forecast,” which represents the core of the financial analysis. The foundation of the model is established in the “Number of User” tab, where user growth is modeled as the primary value driver. The target number of users for the first year was estimated based on expert input rather than arbitrary assumptions. A domain expert with relevant market experience indicated that a realistic initial range for the first year lies between 10,000 and 20,000 users. For planning purposes, the midpoint of this range was chosen in order to create a balanced and plausible baseline scenario. Consequently, the initial user numbers per period are defined such that approximately 15,000 users are reached by the end of the first year. User growth was then calibrated with a specific strategic target in mind. The applied growth rate was selected to ensure that the Serviceable Obtainable Market (SOM) is reached by the end of the first year. Based on market assumptions, the SOM is estimated at approximately 40,000 users. The growth rate therefore reflects an ambitious yet realistic market penetration strategy. In subsequent periods, the growth rate is deliberately reduced to account for increasing market maturity and saturation effects. The time horizon is divided into twelve uniform periods, which can be interpreted as monthly intervals for modeling purposes. Based on the projected user numbers, revenues are derived within the same tab. The model assumes a differentiated revenue structure with multiple user segments. The majority of users are allocated to a basic subscription with a low price point, while a smaller share subscribes to a higher-priced premium offering. In addition, a very small percentage of users is assumed to purchase add-on credits with a fixed basket value. Prices, segment shares, and purchasing behavior are kept constant throughout the forecast period in order to reduce complexity and maintain transparency in the revenue logic. The “Information” tab serves as the central repository for all cost assumptions used in the model. This includes insurance costs, software and licensing fees, app store commissions, and personnel expenses. To ensure transparency and traceability, all key assumptions in this tab are supported by direct links to external sources, which are embedded within the sheet. This allows users of the model to clearly identify the origin of each cost parameter and adjust assumptions if necessary. Separating assumptions from calculations also improves the maintainability and scalability of the model. Personnel costs represent a major component of the overall cost structure. Salary assumptions are based on average market-level compensation for the Munich region, reflecting realistic labor costs for the assumed company location. Personnel expenses are defined on an annual basis and converted into periodic values for integration into the forecast. In the final year of the planning horizon, an additional 0.5 full-time equivalent (FTE) is included to account for the increasing operational workload resulting from the significantly higher number of users. This adjustment reflects the scaling requirements of the business as the platform grows. The “Forecast” tab constitutes the analytical core of the model and presents the operational profit and loss statement on a period-by-period basis. Revenues derived from the user model are combined with cost assumptions from the “Information” tab. First, variable costs are deducted, including payment processing fees and app store commissions, both modeled as fixed percentages of revenue. This approach reflects the typical cost structure of digital platform businesses, where certain expenses scale directly with transaction volume. In addition to variable costs, fixed and semi-fixed operating expenses are incorporated into the forecast, including insurance, licensing fees, and general operating costs. Marketing expenses are modeled in a differentiated manner: during the early phase, marketing is assumed as a fixed periodic amount to support market entry and user acquisition. In later periods, marketing costs are expressed as a percentage of revenue, reflecting a more scalable and efficiency-driven marketing strategy. Personnel costs increase over time in line with the assumptions outlined above and reflect both team expansion and rising operational complexity. Finally, operating profit (EBIT or EBITDA) is calculated as the difference between total revenues and all operating expenses. The forecast clearly illustrates how the business intentionally operates at a loss during the early growth phase in order to build market share and reach critical user thresholds. As scale effects materialize, the cost structure becomes more efficient, and the model demonstrates a transition toward sustainable profitability driven by user growth and the achievement of the targeted SOM.

Sheet Number of User
A1: Wachstum | B1: 1.48 | O1: Revenue
B2: 45658 | C2: 45659 | D2: 45660 | E2: 45661 | F2: 45662 | G2: 45663 | H2: 45664 | I2: 45665 | J2: 45666 | K2: 45667 | L2: 45668 | M2: 45669
A3: Userzahl | B3: 200 | C3: =B3*$B$1 -> 296 | D3: =C3*$B$1 -> 438.08 | E3: =D3*$B$1 -> 648.3584 | F3: =E3*$B$1 -> 959.57043 | G3: =F3*$B$1 -> 1420.1642 | H3: =G3*$B$1 -> 2101.8431 | I3: =H3*$B$1 -> 3110.7277 | J3: =I3*$B$1 -> 4603.8771 | ... M3: =L3*$B$1 -> 14924.812
A4: Preis Basic | B4: =(B3*0.95)*1 -> 190 | C4: =(C3*0.95)*1 -> 281.2 | D4: =(D3*0.95)*1 -> 416.176 | E4: =(E3*0.95)*1 -> 615.94048 | F4: =(F3*0.95)*1 -> 911.59191 | G4: =(G3*0.95)*1 -> 1349.156 | H4: =(H3*0.95)*1 -> 1996.7509 | I4: =(I3*0.95)*1 -> 2955.1914 | ... M4: =(M3*0.95)*1 -> 14178.571
A5: Preis Premium | B5: =(B3-B4)*5 -> 50 | C5: =(C3-C4)*5 -> 74 | D5: =(D3-D4)*5 -> 109.52 | E5: =(E3-E4)*5 -> 162.0896 | F5: =(F3-F4)*5 -> 239.89261 | G5: =(G3-G4)*5 -> 355.04106 | H5: =(H3-H4)*5 -> 525.46077 | I5: =(I3-I4)*5 -> 777.68194 | ... M5: =(M3-M4)*5 -> 3731.203
A6: Preis Credits | B6: =(B3*0.005)*10 -> 10 | C6: =(C3*0.005)*10 -> 14.8 | D6: =(D3*0.005)*10 -> 21.904 | E6: =(E3*0.005)*10 -> 32.41792 | F6: =(F3*0.005)*10 -> 47.978522 | G6: =(G3*0.005)*10 -> 71.008212 | H6: =(H3*0.005)*10 -> 105.09215 | I6: =(I3*0.005)*10 -> 155.53639 | ... M6: =(M3*0.005)*10 -> 746.24059
A7: Umsatz | B7: =B6+B5+B4 -> 250 | C7: =C6+C5+C4 -> 370 | D7: =D6+D5+D4 -> 547.6 | E7: =E6+E5+E4 -> 810.448 | F7: =F6+F5+F4 -> 1199.463 | G7: =G6+G5+G4 -> 1775.2053 | H7: =H6+H5+H4 -> 2627.3038 | I7: =I6+I5+I4 -> 3888.4097 | ... M7: =M6+M5+M4 -> 18656.015 | O7: =SUM(B7:M7) -> 57001.879
A10: Wachstum | B10: 1.05
B11: 46023 | C11: 46024 | D11: 46025 | E11: 46026 | F11: 46027 | G11: 46028 | H11: 46029 | I11: 46030 | J11: 46031 | K11: 46032 | L11: 46033 | M11: 46034
A12: Userzahl | B12: =M3 -> 14924.812 | C12: =B12*$B$10 -> 15671.052 | D12: =C12*$B$10 -> 16454.605 | E12: =D12*$B$10 -> 17277.335 | F12: =E12*$B$10 -> 18141.202 | G12: =F12*$B$10 -> 19048.262 | H12: =G12*$B$10 -> 20000.675 | I12: =H12*$B$10 -> 21000.709 | J12: =I12*$B$10 -> 22050.745 | ... M12: =L12*$B$10 -> 25526.493
A13: Preis Basic | B13: =(B12*0.95)*1 -> 14178.571 | C13: =(C12*0.95)*1 -> 14887.5 | D13: =(D12*0.95)*1 -> 15631.875 | E13: =(E12*0.95)*1 -> 16413.469 | F13: =(F12*0.95)*1 -> 17234.142 | G13: =(G12*0.95)*1 -> 18095.849 | H13: =(H12*0.95)*1 -> 19000.642 | I13: =(I12*0.95)*1 -> 19950.674 | ... M13: =(M12*0.95)*1 -> 24250.168
A14: Preis Premium | B14: =(B12-B13)*5 -> 3731.203 | C14: =(C12-C13)*5 -> 3917.7631 | D14: =(D12-D13)*5 -> 4113.6513 | E14: =(E12-E13)*5 -> 4319.3338 | F14: =(F12-F13)*5 -> 4535.3005 | G14: =(G12-G13)*5 -> 4762.0655 | H14: =(H12-H13)*5 -> 5000.1688 | I14: =(I12-I13)*5 -> 5250.1773 | ... M14: =(M12-M13)*5 -> 6381.6233
A15: Preis Credits | B15: =(B12*0.005)*10 -> 746.24059 | C15: =(C12*0.005)*10 -> 783.55262 | D15: =(D12*0.005)*10 -> 822.73025 | E15: =(E12*0.005)*10 -> 863.86677 | F15: =(F12*0.005)*10 -> 907.0601 | G15: =(G12*0.005)*10 -> 952.41311 | H15: =(H12*0.005)*10 -> 1000.0338 | I15: =(I12*0.005)*10 -> 1050.0355 | ... M15: =(M12*0.005)*10 -> 1276.3247
A16: Umsatz | B16: =B15+B14+B13 -> 18656.015 | C16: =C15+C14+C13 -> 19588.816 | D16: =D15+D14+D13 -> 20568.256 | E16: =E15+E14+E13 -> 21596.669 | F16: =F15+F14+F13 -> 22676.503 | G16: =G15+G14+G13 -> 23810.328 | H16: =H15+H14+H13 -> 25000.844 | I16: =I15+I14+I13 -> 26250.886 | ... M16: =M15+M14+M13 -> 31908.116 | O16: =SUM(B16:M16) -> 296950.15
A19: Wachstum | B19: 1.05
B20: 46023 | C20: 46024 | D20: 46025 | E20: 46026 | F20: 46027 | G20: 46028 | H20: 46029 | I20: 46030 | J20: 46031 | K20: 46032 | L20: 46033 | M20: 46034
A21: Userzahl | B21: =M13 -> 24250.168 | C21: =B21*$B$19 -> 25462.677 | D21: =C21*$B$19 -> 26735.811 | E21: =D21*$B$19 -> 28072.601 | F21: =E21*$B$19 -> 29476.231 | G21: =F21*$B$19 -> 30950.043 | H21: =G21*$B$19 -> 32497.545 | I21: =H21*$B$19 -> 34122.422 | J21: =I21*$B$19 -> 35828.543 | ... M21: =L21*$B$19 -> 41476.018
A22: Preis Basic | B22: =(B21*0.95)*1 -> 23037.66 | C22: =(C21*0.95)*1 -> 24189.543 | D22: =(D21*0.95)*1 -> 25399.02 | E22: =(E21*0.95)*1 -> 26668.971 | F22: =(F21*0.95)*1 -> 28002.42 | G22: =(G21*0.95)*1 -> 29402.541 | H22: =(H21*0.95)*1 -> 30872.668 | I22: =(I21*0.95)*1 -> 32416.301 | ... M22: =(M21*0.95)*1 -> 39402.217
A23: Preis Premium | B23: =(B21-B22)*5 -> 6062.5421 | C23: =(C21-C22)*5 -> 6365.6692 | D23: =(D21-D22)*5 -> 6683.9527 | E23: =(E21-E22)*5 -> 7018.1503 | F23: =(F21-F22)*5 -> 7369.0578 | G23: =(G21-G22)*5 -> 7737.5107 | H23: =(H21-H22)*5 -> 8124.3863 | I23: =(I21-I22)*5 -> 8530.6056 | ... M23: =(M21-M22)*5 -> 10369.004
A24: Preis Credits | B24: =(B21*0.005)*10 -> 1212.5084 | C24: =(C21*0.005)*10 -> 1273.1338 | D24: =(D21*0.005)*10 -> 1336.7905 | E24: =(E21*0.005)*10 -> 1403.6301 | F24: =(F21*0.005)*10 -> 1473.8116 | G24: =(G21*0.005)*10 -> 1547.5021 | H24: =(H21*0.005)*10 -> 1624.8773 | I24: =(I21*0.005)*10 -> 1706.1211 | ... M24: =(M21*0.005)*10 -> 2073.8009
A25: Umsatz | B25: =B24+B23+B22 -> 30312.711 | C25: =C24+C23+C22 -> 31828.346 | D25: =D24+D23+D22 -> 33419.763 | E25: =E24+E23+E22 -> 35090.752 | F25: =F24+F23+F22 -> 36845.289 | G25: =G24+G23+G22 -> 38687.554 | H25: =H24+H23+H22 -> 40621.931 | I25: =I24+I23+I22 -> 42653.028 | ... M25: =M24+M23+M22 -> 51845.022 | O25: =SUM(B25:M25) -> 482491.25
A28: Wachstum | B28: 1.05
B29: 46023 | C29: 46024 | D29: 46025 | E29: 46026 | F29: 46027 | G29: 46028 | H29: 46029 | I29: 46030 | J29: 46031 | K29: 46032 | L29: 46033 | M29: 46034
A30: Userzahl | B30: =M22 -> 39402.217 | C30: =B30*$B$28 -> 41372.328 | D30: =C30*$B$28 -> 43440.944 | E30: =D30*$B$28 -> 45612.991 | F30: =E30*$B$28 -> 47893.641 | G30: =F30*$B$28 -> 50288.323 | H30: =G30*$B$28 -> 52802.739 | I30: =H30*$B$28 -> 55442.876 | J30: =I30*$B$28 -> 58215.02 | ... M30: =L30*$B$28 -> 67391.162
A31: Preis Basic | B31: =(B30*0.95)*1 -> 37432.106 | C31: =(C30*0.95)*1 -> 39303.711 | D31: =(D30*0.95)*1 -> 41268.897 | E31: =(E30*0.95)*1 -> 43332.342 | F31: =(F30*0.95)*1 -> 45498.959 | G31: =(G30*0.95)*1 -> 47773.907 | H31: =(H30*0.95)*1 -> 50162.602 | I31: =(I30*0.95)*1 -> 52670.732 | ... M31: =(M30*0.95)*1 -> 64021.604
A32: Preis Premium | B32: =(B30-B31)*5 -> 9850.5542 | C32: =(C30-C31)*5 -> 10343.082 | D32: =(D30-D31)*5 -> 10860.236 | E32: =(E30-E31)*5 -> 11403.248 | F32: =(F30-F31)*5 -> 11973.41 | G32: =(G30-G31)*5 -> 12572.081 | H32: =(H30-H31)*5 -> 13200.685 | I32: =(I30-I31)*5 -> 13860.719 | ... M32: =(M30-M31)*5 -> 16847.791
A33: Preis Credits | B33: =(B30*0.005)*10 -> 1970.1108 | C33: =(C30*0.005)*10 -> 2068.6164 | D33: =(D30*0.005)*10 -> 2172.0472 | E33: =(E30*0.005)*10 -> 2280.6496 | F33: =(F30*0.005)*10 -> 2394.682 | G33: =(G30*0.005)*10 -> 2514.4161 | H33: =(H30*0.005)*10 -> 2640.1369 | I33: =(I30*0.005)*10 -> 2772.1438 | ... M33: =(M30*0.005)*10 -> 3369.5581
A34: Umsatz | B34: =B33+B32+B31 -> 49252.771 | C34: =C33+C32+C31 -> 51715.409 | D34: =D33+D32+D31 -> 54301.18 | E34: =E33+E32+E31 -> 57016.239 | F34: =F33+F32+F31 -> 59867.051 | G34: =G33+G32+G31 -> 62860.403 | H34: =H33+H32+H31 -> 66003.424 | I34: =I33+I32+I31 -> 69303.595 | ... M34: =M33+M32+M31 -> 84238.953 | O34: =SUM(B34:M34) -> 783962.59

Sheet Information
D1: Sources:
A3: Insurance Cost: | B3: =SUM(B4:B7) -> 165.66667
A4: Public liability insurance | B4: 22 | D4: Online-Antrag | Online-Rechner IT-Haftpflicht
A5: Cyber insurance | B5: 38 | E5: Versicherungsumfang - Hiscox
A6: D&O insurance | B6: =668/12 -> 55.666667 | E6: Tarifvergleich | Bernhard Assekuranz B2C
A7: Legal protection | B7: 50 | E7: ROLAND Rechtsschutz – Besser miteinander.
A10: License Fees: | B10: =SUM(B11:B13) -> 1103
A11: MS Office | B11: =5*20.6 -> 103 | D11: Pläne und Preise für Microsoft 365 Business vergleichen | Microsoft 365
A12: Database hosting | B12: 800 | D12: Preise für das Datenbank-Hosting - Kinsta®
A13: Other Subscriptions | B13: 200
A16: App Store Fees: | B16: 0.15 | D16: App Store Small Business Program - Apple Developer
A21: Personal Cost: | B21: =B22/12 -> 11535.333
A22: Yearly | B22: =(B23*B24)+(B23*B24*B25) -> 138424
A23: Salary | B23: 57200 | D23: Das ist das Durchschnittsgehalt in München | kununu News
A24: FTE | B24: 2
A25: Employer contribution | B25: 0.21 | D25: Lohnnebenkosten: Was zahlt der Arbeitgeber? | HR WORKS
A28: BEP | B28: Year 3 | D28: When will my startup make money? A timeline of startup profitability | Startups Magazine
A31: Marketing expenses:
A32: Year 1 | B32: 0.2 | D32: Different because of the One Time Pre-Launch Package
A33: Year 2 | B33: 0.1 | D33: https://www.fuer-gruender.de/wissen/existenzgruendung-planen/marketingmix/marketingbudget/
A34: Year 3 | B34: 0.1
A37: Payment Fees:
A38: PayPal | B38: 0.0299 | D38: Fees | Merchant and Business | PayPal US
A41: Rent: | B41: =B42*B43 -> 892.5
A42: Fix Desk: | B42: 357 | D42: Plug and Play Coworking München | Alle Infos, Bilder, Preise
A43: FTE | B43: 2.5

Sheet Forecast
B2: 46023 | C2: 46024 | D2: 46025 | E2: 46026 | F2: 46027 | G2: 46028 | H2: 46029 | I2: 46030 | J2: 46031 | K2: 46032 | L2: 46033 | M2: 46034
A3: Revenue | B3: ='Number of User'!B7 -> 250 | C3: ='Number of User'!C7 -> 370 | D3: ='Number of User'!D7 -> 547.6 | E3: ='Number of User'!E7 -> 810.448 | F3: ='Number of User'!F7 -> 1199.463 | G3: ='Number of User'!G7 -> 1775.2053 | H3: ='Number of User'!H7 -> 2627.3038 | I3: ='Number of User'!I7 -> 3888.4097 | ... M3: ='Number of User'!M7 -> 18656.015 | O3: =SUM(B3:M3) -> 57001.879
A4: Membership | B4: ='Number of User'!B4+'Number of User'!B5 -> 240 | C4: ='Number of User'!C4+'Number of User'!C5 -> 355.2 | D4: ='Number of User'!D4+'Number of User'!D5 -> 525.696 | E4: ='Number of User'!E4+'Number of User'!E5 -> 778.03008 | F4: ='Number of User'!F4+'Number of User'!F5 -> 1151.4845 | G4: ='Number of User'!G4+'Number of User'!G5 -> 1704.1971 | H4: ='Number of User'!H4+'Number of User'!H5 -> 2522.2117 | I4: ='Number of User'!I4+'Number of User'!I5 -> 3732.8733 | ... M4: ='Number of User'!M4+'Number of User'!M5 -> 17909.774 | O4: =SUM(B4:M4) -> 54721.804
A5: Additional | B5: ='Number of User'!B6 -> 10 | C5: ='Number of User'!C6 -> 14.8 | D5: ='Number of User'!D6 -> 21.904 | E5: ='Number of User'!E6 -> 32.41792 | F5: ='Number of User'!F6 -> 47.978522 | G5: ='Number of User'!G6 -> 71.008212 | H5: ='Number of User'!H6 -> 105.09215 | I5: ='Number of User'!I6 -> 155.53639 | ... M5: ='Number of User'!M6 -> 746.24059 | O5: =SUM(B5:M5) -> 2280.0752
A7: Other operating expenses | B7: =SUM(B8:B14) -> 11713.642 | C7: =SUM(C8:C14) -> 1985.2297 | D7: =SUM(D8:D14) -> 2017.1799 | E7: =SUM(E8:E14) -> 2064.4663 | F7: =SUM(F8:F14) -> 2134.4501 | G7: =SUM(G8:G14) -> 2238.0261 | H7: =SUM(H8:H14) -> 2391.3186 | I7: =SUM(I8:I14) -> 2618.1916 | ... M7: =SUM(M8:M14) -> 5274.8837 | O7: =SUM(B7:M7) -> 43028.638
A8: Opertation and business expenses (BGA) | B8: 10000 | C8: 250 | D8: 250 | E8: 250 | F8: 250 | G8: 250 | H8: 250 | I8: 250 | J8: 250 | K8: 250 | L8: 250 | M8: 250 | O8: =SUM(B8:M8) -> 12750
A9: Payment Costs | B9: =(B3*0.0299) -> 7.475 | C9: =(C3*0.0299) -> 11.063 | D9: =(D3*0.0299) -> 16.37324 | E9: =(E3*0.0299) -> 24.232395 | F9: =(F3*0.0299) -> 35.863945 | G9: =(G3*0.0299) -> 53.078638 | H9: =(H3*0.0299) -> 78.556385 | I9: =(I3*0.0299) -> 116.26345 | ... M9: =(M3*0.0299) -> 557.81484 | O9: =SUM(B9:M9) -> 1704.3562
A10: Assurance | B10: =Information!B3 -> 165.66667 | C10: =B10 -> 165.66667 | D10: =C10 -> 165.66667 | E10: =D10 -> 165.66667 | F10: =E10 -> 165.66667 | G10: =F10 -> 165.66667 | H10: =G10 -> 165.66667 | I10: =H10 -> 165.66667 | J10: =I10 -> 165.66667 | ... M10: =L10 -> 165.66667 | O10: =SUM(B10:M10) -> 1988
A11: License Fees | B11: =Information!B10 -> 1103 | C11: =B11 -> 1103 | D11: =C11 -> 1103 | E11: =D11 -> 1103 | F11: =E11 -> 1103 | G11: =F11 -> 1103 | H11: =G11 -> 1103 | I11: =H11 -> 1103 | J11: =I11 -> 1103 | ... M11: =L11 -> 1103 | O11: =SUM(B11:M11) -> 13236
A12: Expenses | B12: 400 | C12: 400 | D12: 400 | E12: 400 | F12: 400 | G12: 400 | H12: 400 | I12: 400 | J12: 400 | K12: 400 | L12: 400 | M12: 400 | O12: =SUM(B12:M12) -> 4800
A13: AppStore Fee | B13: =B3*0.15 -> 37.5 | C13: =C3*0.15 -> 55.5 | D13: =D3*0.15 -> 82.14 | E13: =E3*0.15 -> 121.5672 | F13: =F3*0.15 -> 179.91946 | G13: =G3*0.15 -> 266.28079 | H13: =H3*0.15 -> 394.09558 | I13: =I3*0.15 -> 583.26145 | ... M13: =M3*0.15 -> 2798.4022 | O13: =SUM(B13:M13) -> 8550.2819
A15: Marketing expenses | B15: 6000 | C15: 500 | D15: 500 | E15: 500 | F15: 500 | G15: 500 | H15: 500 | I15: 500 | J15: 500 | K15: 500 | L15: 500 | M15: 500 | O15: =SUM(B15:M15) -> 11500
A17: Personnel expenses | B17: =Information!B21 -> 11535.333 | C17: =B17 -> 11535.333 | D17: =C17 -> 11535.333 | E17: =D17 -> 11535.333 | F17: =E17 -> 11535.333 | G17: =F17 -> 11535.333 | H17: =G17 -> 11535.333 | I17: =H17 -> 11535.333 | J17: =I17 -> 11535.333 | ... M17: =L17 -> 11535.333 | O17: =SUM(B17:M17) -> 138424
A20: EBITDA | B20: =B3-(B7+B17+B15) -> -28998.975 | C20: =C3-(C7+C17+C15) -> -13650.563 | D20: =D3-(D7+D17+D15) -> -13504.913 | E20: =E3-(E7+E17+E15) -> -13289.352 | F20: =F3-(F7+F17+F15) -> -12970.32 | G20: =G3-(G7+G17+G15) -> -12498.154 | H20: =H3-(H7+H17+H15) -> -11799.348 | I20: =I3-(I7+I17+I15) -> -10765.115 | ... M20: =M3-(M7+M17+M15) -> 1345.7978 | O20: =SUM(B20:M20) -> -135950.76
B23: 46388 | C23: 46419 | D23: 46447 | E23: 46478 | F23: 46508 | G23: 46539 | H23: 46569 | I23: 46600 | J23: 46631 | K23: 46661 | L23: 46692 | M23: 46722
A24: Revenue | B24: ='Number of User'!B16 -> 18656.015 | C24: ='Number of User'!C16 -> 19588.816 | D24: ='Number of User'!D16 -> 20568.256 | E24: ='Number of User'!E16 -> 21596.669 | F24: ='Number of User'!F16 -> 22676.503 | G24: ='Number of User'!G16 -> 23810.328 | H24: ='Number of User'!H16 -> 25000.844 | I24: ='Number of User'!I16 -> 26250.886 | ... M24: ='Number of User'!M16 -> 31908.116 | O24: =SUM(B24:M24) -> 296950.15
A25: Membership | B25: ='Number of User'!B13+'Number of User'!B14 -> 17909.774 | C25: ='Number of User'!C13+'Number of User'!C14 -> 18805.263 | D25: ='Number of User'!D13+'Number of User'!D14 -> 19745.526 | E25: ='Number of User'!E13+'Number of User'!E14 -> 20732.802 | F25: ='Number of User'!F13+'Number of User'!F14 -> 21769.443 | G25: ='Number of User'!G13+'Number of User'!G14 -> 22857.915 | H25: ='Number of User'!H13+'Number of User'!H14 -> 24000.81 | I25: ='Number of User'!I13+'Number of User'!I14 -> 25200.851 | ... M25: ='Number of User'!M13+'Number of User'!M14 -> 30631.792 | O25: =SUM(B25:M25) -> 285072.14
A26: Additional | B26: ='Number of User'!B15 -> 746.24059 | C26: ='Number of User'!C15 -> 783.55262 | D26: ='Number of User'!D15 -> 822.73025 | E26: ='Number of User'!E15 -> 863.86677 | F26: ='Number of User'!F15 -> 907.0601 | G26: ='Number of User'!G15 -> 952.41311 | H26: ='Number of User'!H15 -> 1000.0338 | I26: ='Number of User'!I15 -> 1050.0355 | ... M26: ='Number of User'!M15 -> 1276.3247 | O26: =SUM(B26:M26) -> 11878.006
A28: Other operating expenses | B28: =SUM(B29:B35) -> 5995.1837 | C28: =SUM(C29:C35) -> 6162.9946 | D28: =SUM(D29:D35) -> 6339.196 | E28: =SUM(E29:E35) -> 6524.2074 | F28: =SUM(F29:F35) -> 6718.4695 | G28: =SUM(G29:G35) -> 6922.4446 | H28: =SUM(H29:H35) -> 7136.6185 | I28: =SUM(I29:I35) -> 7361.5011 | ... M28: =SUM(M29:M35) -> 8379.2368 | O28: =SUM(B28:M28) -> 85088.932
A29: Opertation and business expenses (BGA) | B29: 500 | C29: 500 | D29: 500 | E29: 500 | F29: 500 | G29: 500 | H29: 500 | I29: 500 | J29: 500 | K29: 500 | L29: 500 | M29: 500 | O29: =SUM(B29:M29) -> 6000
A30: Payment Costs | B30: =B24*0.0299 -> 557.81484 | C30: =C24*0.0299 -> 585.70559 | D30: =D24*0.0299 -> 614.99086 | E30: =E24*0.0299 -> 645.74041 | F30: =F24*0.0299 -> 678.02743 | G30: =G24*0.0299 -> 711.9288 | H30: =H24*0.0299 -> 747.52524 | I30: =I24*0.0299 -> 784.9015 | ... M30: =M24*0.0299 -> 954.05268 | O30: =SUM(B30:M30) -> 8878.8094
A31: Assurance | B31: =B10*1.3 -> 215.36667 | C31: =C10*1.3 -> 215.36667 | D31: =D10*1.3 -> 215.36667 | E31: =E10*1.3 -> 215.36667 | F31: =F10*1.3 -> 215.36667 | G31: =G10*1.3 -> 215.36667 | H31: =H10*1.3 -> 215.36667 | I31: =I10*1.3 -> 215.36667 | ... M31: =M10*1.3 -> 215.36667 | O31: =SUM(B31:M31) -> 2584.4
A32: License Fees | B32: =B11*1.2 -> 1323.6 | C32: =C11*1.2 -> 1323.6 | D32: =D11*1.2 -> 1323.6 | E32: =E11*1.2 -> 1323.6 | F32: =F11*1.2 -> 1323.6 | G32: =G11*1.2 -> 1323.6 | H32: =H11*1.2 -> 1323.6 | I32: =I11*1.2 -> 1323.6 | ... M32: =M11*1.2 -> 1323.6 | O32: =SUM(B32:M32) -> 15883.2
A33: Expenses | B33: 600 | C33: 600 | D33: 600 | E33: 600 | F33: 600 | G33: 600 | H33: 600 | I33: 600 | J33: 600 | K33: 600 | L33: 600 | M33: 600 | O33: =SUM(B33:M33) -> 7200
A34: AppStore Fee | B34: =B24*0.15 -> 2798.4022 | C34: =C24*0.15 -> 2938.3223 | D34: =D24*0.15 -> 3085.2385 | E34: =E24*0.15 -> 3239.5004 | F34: =F24*0.15 -> 3401.4754 | G34: =G24*0.15 -> 3571.5492 | H34: =H24*0.15 -> 3750.1266 | I34: =I24*0.15 -> 3937.633 | ... M34: =M24*0.15 -> 4786.2175 | O34: =SUM(B34:M34) -> 44542.522
A36: Marketing expenses | B36: =B24*0.1 -> 1865.6015 | C36: =C24*0.1 -> 1958.8816 | D36: =D24*0.1 -> 2056.8256 | E36: =E24*0.1 -> 2159.6669 | F36: =F24*0.1 -> 2267.6503 | G36: =G24*0.1 -> 2381.0328 | H36: =H24*0.1 -> 2500.0844 | I36: =I24*0.1 -> 2625.0886 | ... M36: =M24*0.1 -> 3190.8116 | O36: =SUM(B36:M36) -> 29695.015
A38: Personnel expenses | B38: =Information!B21*1.03 -> 11881.393 | C38: =B38 -> 11881.393 | D38: =C38 -> 11881.393 | E38: =D38 -> 11881.393 | F38: =E38 -> 11881.393 | G38: =F38 -> 11881.393 | H38: =G38 -> 11881.393 | I38: =H38 -> 11881.393 | J38: =I38 -> 11881.393 | ... M38: =L38 -> 11881.393 | O38: =SUM(B38:M38) -> 142576.72
A41: EBITDA | B41: =B24-(B28+B38+B36) -> -1086.1637 | C41: =C24-(C28+C38+C36) -> -414.45392 | D41: =D24-(D28+D38+D36) -> 290.84139 | E41: =E24-(E28+E38+E36) -> 1031.4015 | F41: =F24-(F28+F38+F36) -> 1808.9895 | G41: =G24-(G28+G38+G36) -> 2625.457 | H41: =H24-(H28+H38+H36) -> 3482.7479 | I41: =I24-(I28+I38+I36) -> 4382.9032 | ... M41: =M24-(M28+M38+M36) -> 8456.6746 | O41: =SUM(B41:M41) -> 39589.482
B44: 46753 | C44: 46784 | D44: 46813 | E44: 46844 | F44: 46874 | G44: 46905 | H44: 46935 | I44: 46966 | J44: 46997 | K44: 47027 | L44: 47058 | M44: 47088
A45: Revenue | B45: =SUM(B46:B48) -> 31812.711 | C45: =SUM(C46:C48) -> 33328.346 | D45: =SUM(D46:D48) -> 34919.763 | E45: =SUM(E46:E48) -> 36590.752 | F45: =SUM(F46:F48) -> 38345.289 | G45: =SUM(G46:G48) -> 40187.554 | H45: =SUM(H46:H48) -> 42121.931 | I45: =SUM(I46:I48) -> 44153.028 | ... M45: =SUM(M46:M48) -> 53345.022 | O45: =SUM(B45:M45) -> 500491.25
A46: Membership | B46: ='Number of User'!B22+'Number of User'!B23 -> 29100.202 | C46: ='Number of User'!C22+'Number of User'!C23 -> 30555.212 | D46: ='Number of User'!D22+'Number of User'!D23 -> 32082.973 | E46: ='Number of User'!E22+'Number of User'!E23 -> 33687.122 | F46: ='Number of User'!F22+'Number of User'!F23 -> 35371.478 | G46: ='Number of User'!G22+'Number of User'!G23 -> 37140.051 | H46: ='Number of User'!H22+'Number of User'!H23 -> 38997.054 | I46: ='Number of User'!I22+'Number of User'!I23 -> 40946.907 | ... M46: ='Number of User'!M22+'Number of User'!M23 -> 49771.221 | O46: =SUM(B46:M46) -> 463191.6
A47: Additional | B47: ='Number of User'!B24 -> 1212.5084 | C47: ='Number of User'!C24 -> 1273.1338 | D47: ='Number of User'!D24 -> 1336.7905 | E47: ='Number of User'!E24 -> 1403.6301 | F47: ='Number of User'!F24 -> 1473.8116 | G47: ='Number of User'!G24 -> 1547.5021 | H47: ='Number of User'!H24 -> 1624.8773 | I47: ='Number of User'!I24 -> 1706.1211 | ... M47: ='Number of User'!M24 -> 2073.8009 | O47: =SUM(B47:M47) -> 19299.65
A48: B2B | B48: 1500 | C48: 1500 | D48: 1500 | E48: 1500 | F48: 1500 | G48: 1500 | H48: 1500 | I48: 1500 | J48: 1500 | K48: 1500 | L48: 1500 | M48: 1500 | O48: =SUM(B48:M48) -> 18000
A50: Other operating expenses | B50: =SUM(B51:B58) -> 11583.903 | C50: =SUM(C51:C58) -> 9856.5661 | D50: =SUM(D51:D58) -> 10142.862 | E50: =SUM(E51:E58) -> 10443.473 | F50: =SUM(F51:F58) -> 10759.114 | G50: =SUM(G51:G58) -> 11090.538 | H50: =SUM(H51:H58) -> 11438.532 | I50: =SUM(I51:I58) -> 11803.926 | ... M50: =SUM(M51:M58) -> 13457.566 | O50: =SUM(B50:M50) -> 138367.94
A51: Opertation and business expenses (BGA) | B51: 2500 | C51: 500 | D51: 500 | E51: 500 | F51: 500 | G51: 500 | H51: 500 | I51: 500 | J51: 500 | K51: 500 | L51: 500 | M51: 500 | O51: =SUM(B51:M51) -> 8000
A52: Payment Costs | B52: =B45*0.0299 -> 951.20005 | C52: =C45*0.0299 -> 996.51755 | D52: =D45*0.0299 -> 1044.1009 | E52: =E45*0.0299 -> 1094.0635 | F52: =F45*0.0299 -> 1146.5241 | G52: =G45*0.0299 -> 1201.6079 | H52: =H45*0.0299 -> 1259.4457 | I52: =I45*0.0299 -> 1320.1755 | ... M52: =M45*0.0299 -> 1595.0162 | O52: =SUM(B52:M52) -> 14964.688
A53: Assurance | B53: =B31*1.3 -> 279.97667 | C53: =C31*1.3 -> 279.97667 | D53: =D31*1.3 -> 279.97667 | E53: =E31*1.3 -> 279.97667 | F53: =F31*1.3 -> 279.97667 | G53: =G31*1.3 -> 279.97667 | H53: =H31*1.3 -> 279.97667 | I53: =I31*1.3 -> 279.97667 | ... M53: =M31*1.3 -> 279.97667 | O53: =SUM(B53:M53) -> 3359.72
A54: License Fees | B54: =B32*1.2 -> 1588.32 | C54: =C32*1.2 -> 1588.32 | D54: =D32*1.2 -> 1588.32 | E54: =E32*1.2 -> 1588.32 | F54: =F32*1.2 -> 1588.32 | G54: =G32*1.2 -> 1588.32 | H54: =H32*1.2 -> 1588.32 | I54: =I32*1.2 -> 1588.32 | ... M54: =M32*1.2 -> 1588.32 | O54: =SUM(B54:M54) -> 19059.84
A55: Expenses | B55: 600 | C55: 600 | D55: 600 | E55: 600 | F55: 600 | G55: 600 | H55: 600 | I55: 600 | J55: 600 | K55: 600 | L55: 600 | M55: 600 | O55: =SUM(B55:M55) -> 7200
A56: AppStore Fee | B56: =B45*0.15 -> 4771.9066 | C56: =C45*0.15 -> 4999.2519 | D56: =D45*0.15 -> 5237.9645 | E56: =E45*0.15 -> 5488.6127 | F56: =F45*0.15 -> 5751.7934 | G56: =G45*0.15 -> 6028.133 | H56: =H45*0.15 -> 6318.2897 | I56: =I45*0.15 -> 6622.9542 | ... M56: =M45*0.15 -> 8001.7533 | O56: =SUM(B56:M56) -> 75073.687
...

Sheet Overview P&L
B3: 2026 | C3: 2027 | D3: 2028
A4: Revenue | B4: =Forecast!O3 -> 57001.879 | C4: =Forecast!O24 -> 296950.15 | D4: =Forecast!O45 -> 500491.25
A5: Membership | B5: =Forecast!O4 -> 54721.804 | C5: =Forecast!O25 -> 285072.14 | D5: =Forecast!O46 -> 463191.6
A6: Additional | B6: =Forecast!O5 -> 2280.0752 | C6: =Forecast!O26 -> 11878.006 | D6: =Forecast!O47 -> 19299.65
A7: B2B | D7: =Forecast!O48 -> 18000
A9: Personnel costs | B9: =Forecast!O17 -> 138424 | C9: =Forecast!O38 -> 142576.72 | D9: =Forecast!O61 -> 213865.08
A11: Marketing Cost | B11: =Forecast!O15 -> 11500 | C11: =Forecast!O36 -> 29695.015 | D11: =Forecast!O59 -> 50049.125
A13: Other operating expenses | B13: =Forecast!O7 -> 43028.638 | C13: =Forecast!O28 -> 85088.932 | D13: =Forecast!O50 -> 138367.94
A14: Opertation and business expenses (BGA) | B14: =Forecast!O8 -> 12750 | C14: =Forecast!O29 -> 6000 | D14: =Forecast!O51 -> 8000
A15: Payment Costs | B15: =Forecast!O9 -> 1704.3562 | C15: =Forecast!O30 -> 8878.8094 | D15: =Forecast!O52 -> 14964.688
A16: Assurance | B16: =Forecast!O10 -> 1988 | C16: =Forecast!O31 -> 2584.4 | D16: =Forecast!O53 -> 3359.72
A17: License Fees | B17: =Forecast!O11 -> 13236 | C17: =Forecast!O32 -> 15883.2 | D17: =Forecast!O54 -> 19059.84
A18: Expenses | B18: =Forecast!O12 -> 4800 | C18: =Forecast!O33 -> 7200 | D18: =Forecast!O55 -> 7200
A19: AppStore Fee | B19: =Forecast!O13 -> 8550.2819 | C19: =Forecast!O34 -> 44542.522 | D19: =Forecast!O56 -> 75073.687
A21: EBIT | B21: =B4-(B9+B11+B13) -> -135950.76 | C21: =C4-(C9+C11+C13) -> 39589.482 | D21: =D4-(D9+D11+D13) -> 98209.109
